<robot
  name="9.SLDASM">
  <link
    name="Taz">
    <inertial>
      <origin
        xyz="0.0087165 3.8567E-07 -0.051657"
        rpy="0 0 0" />
      <mass
        value="4.1266" />
      <inertia
        ixx="0.028323"
        ixy="-8.9375E-07"
        ixz="-0.00010747"
        iyy="0.011957"
        iyz="-1.5565E-07"
        izz="0.033839" />
    </inertial>
    <visual>
      <origin
        xyz="0 0 0"
        rpy="0 0 0" />
      <geometry>
        <mesh
          filename="package://9.SLDASM/meshes/Taz.STL" />
      </geometry>
      <material
        name="temp">
        <color
          rgba="1 1 1 1" />
      </material>
    </visual>
    <collision>
      <origin
        xyz="0 0 0"
        rpy="0 0 0" />
      <geometry>
        <mesh
          filename="package://9.SLDASM/meshes/Taz.STL" />
      </geometry>
    </collision>
  </link>
 <link
    name="Torso">
    <inertial>
      <origin
        xyz="-0.011272 2.1289E-05 0.16761"
        rpy="0 0 0" />
      <mass
        value="17.759" />
      <inertia
        ixx="0.23995"
        ixy="2.9043E-05"
        ixz="-0.0089394"
        iyy="0.21472"
        iyz="2.725E-05"
        izz="0.17329" />
    </inertial>
    <visual>
      <origin
        xyz="0 0 0"
        rpy="0 0 0" />
      <geometry>
        <mesh
          filename="package://9.SLDASM/meshes/Torso.STL" />
      </geometry>
      <material
        name="temp">
        <color
          rgba="1 1 1 1" />
      </material>
    </visual>
    <collision>
      <origin
        xyz="0 0 0"
        rpy="0 0 0" />
      <geometry>
        <mesh
          filename="package://9.SLDASM/meshes/Torso.STL" />
      </geometry>
    </collision>
  </link>
  <joint
    name="TorsoYaw"
    type="revolute">
    <origin
      xyz="0 0 0"
      rpy="0 0 0" />
    <parent
      link="Taz" />
    <child
      link="Torso" />
    <axis
      xyz="0 0 1" />
    <limit
      lower="-1"
      upper="1"
      effort="1000"
      velocity="10" />
    <dynamics
      damping="1"
      friction="1" />
  </joint>
  <link
    name="RShoulder1">
    <inertial>
      <origin
        xyz="0.0119949555242503 -0.0447411869608325 0.0124494864503562"
        rpy="0 0 0" />
      <mass
        value="0.702386181282745" />
      <inertia
        ixx="0.00106974111532826"
        ixy="-4.21603468717136E-05"
        ixz="-1.03125854224853E-05"
        iyy="0.00208349580288403"
        iyz="-1.38983012380039E-05"
        izz="0.00181178156982158" />
    </inertial>
    <visual>
      <origin
        xyz="0 0 0"
        rpy="0 0 0" />
      <geometry>
        <mesh
          filename="package://9.SLDASM/meshes/RShoulder1.STL" />
      </geometry>
      <material
        name="temp">
        <color
          rgba="1 1 1 1" />
      </material>
    </visual>
    <collision>
      <origin
        xyz="0 0 0"
        rpy="0 0 0" />
      <geometry>
        <mesh
          filename="package://9.SLDASM/meshes/RShoulder1.STL" />
      </geometry>
    </collision>
  </link>
  <joint
    name="RShoulder1Pitch"
    type="revolute">
    <origin
      xyz="0.0081623 -0.12299 0.255"
      rpy="0 0 0.18497" />
    <parent
      link="Torso" />
    <child
      link="RShoulder1" />
    <axis
      xyz="0 1 0" />
    <limit
      lower="-1"
      upper="1"
      effort="1000"
      velocity="10" />
    <dynamics
      damping="1"
      friction="1" />
  </joint>
  <link
    name="RShoulder2">
    <inertial>
      <origin
        xyz="0.0512392226930269 -0.0264142906322848 0.00120771182202012"
        rpy="0 0 0" />
      <mass
        value="0.710524721499474" />
      <inertia
        ixx="0.00114546631945158"
        ixy="1.88298954427073E-05"
        ixz="-1.50894836583682E-06"
        iyy="0.000678757117060237"
        iyz="-1.74663088662221E-05"
        izz="0.00118255499414833" />
    </inertial>
    <visual>
      <origin
        xyz="0 0 0"
        rpy="0 0 0" />
      <geometry>
        <mesh
          filename="package://9.SLDASM/meshes/RShoulder2.STL" />
      </geometry>
      <material
        name="temp">
        <color
          rgba="1 1 1 1" />
      </material>
    </visual>
    <collision>
      <origin
        xyz="0 0 0"
        rpy="0 0 0" />
      <geometry>
        <mesh
          filename="package://9.SLDASM/meshes/RShoulder2.STL" />
      </geometry>
    </collision>
  </link>
  <joint
    name="RShoulder2Roll"
    type="revolute">
    <origin
      xyz="-0.05 -0.0699 0"
      rpy="0 0 0" />
    <parent
      link="RShoulder1" />
    <child
      link="RShoulder2" />
    <axis
      xyz="1 0 0" />
    <limit
      lower="-1"
      upper="1"
      effort="1000"
      velocity="10" />
    <dynamics
      damping="1"
      friction="1" />
  </joint>
  <link
    name="RShoulder3">
    <inertial>
      <origin
        xyz="-0.000285512379694923 -0.0754223955241937 0.000610317810293803"
        rpy="0 0 0" />
      <mass
        value="0.923986049465604" />
      <inertia
        ixx="0.00281485701688073"
        ixy="-2.01727821238317E-05"
        ixz="1.60626232828031E-06"
        iyy="0.0011174015837173"
        iyz="-2.74275836340887E-05"
        izz="0.0024862009088974" />
    </inertial>
    <visual>
      <origin
        xyz="0 0 0"
        rpy="0 0 0" />
      <geometry>
        <mesh
          filename="package://9.SLDASM/meshes/RShoulder3.STL" />
      </geometry>
      <material
        name="temp">
        <color
          rgba="1 1 1 1" />
      </material>
    </visual>
    <collision>
      <origin
        xyz="0 0 0"
        rpy="0 0 0" />
      <geometry>
        <mesh
          filename="package://9.SLDASM/meshes/RShoulder3.STL" />
      </geometry>
    </collision>
  </link>
  <joint
    name="RShoulder3Pitch"
    type="revolute">
    <origin
      xyz="0.04975 -0.0847 0"
      rpy="0 0 0" />
    <parent
      link="RShoulder2" />
    <child
      link="RShoulder3" />
    <axis
      xyz="0 1 0" />
    <limit
      lower="-1"
      upper="1"
      effort="1000"
      velocity="10" />
    <dynamics
      damping="1"
      friction="1" />
  </joint>
  <link
    name="RElbow">
    <inertial>
      <origin
        xyz="-0.00648692940415502 -0.0268889649873131 -0.0306512428440622"
        rpy="0 0 0" />
      <mass
        value="0.0670881837495098" />
      <inertia
        ixx="0.000109022839821225"
        ixy="6.73954004368908E-06"
        ixz="-1.67802137931819E-07"
        iyy="8.74563299787509E-05"
        iyz="-6.59809657822101E-07"
        izz="0.000124724907558027" />
    </inertial>
    <visual>
      <origin
        xyz="0 0 0"
        rpy="0 0 0" />
      <geometry>
        <mesh
          filename="package://9.SLDASM/meshes/RElbow.STL" />
      </geometry>
      <material
        name="temp">
        <color
          rgba="1 1 1 1" />
      </material>
    </visual>
    <collision>
      <origin
        xyz="0 0 0"
        rpy="0 0 0" />
      <geometry>
        <mesh
          filename="package://9.SLDASM/meshes/RElbow.STL" />
      </geometry>
    </collision>
  </link>
  <joint
    name="RElbowYaw"
    type="revolute">
    <origin
      xyz="0.01 -0.1485 0.0305"
      rpy="0 0 0" />
    <parent
      link="RShoulder3" />
    <child
      link="RElbow" />
    <axis
      xyz="0 0 1" />
    <limit
      lower="-1"
      upper="1"
      effort="1000"
      velocity="10" />
    <dynamics
      damping="1"
      friction="1" />
  </joint>
  <link
    name="RArm">
    <inertial>
      <origin
        xyz="3.3908891167167E-07 -0.0546541724381555 0.000345780744001434"
        rpy="0 0 0" />
      <mass
        value="0.69882147680058" />
      <inertia
        ixx="0.00106001711630364"
        ixy="-6.29306886375941E-09"
        ixz="2.13066980114719E-09"
        iyy="0.000705561415630704"
        iyz="3.04202034019262E-06"
        izz="0.00107112324627601" />
    </inertial>
    <visual>
      <origin
        xyz="0 0 0"
        rpy="0 0 0" />
      <geometry>
        <mesh
          filename="package://9.SLDASM/meshes/RArm.STL" />
      </geometry>
      <material
        name="temp">
        <color
          rgba="1 1 1 1" />
      </material>
    </visual>
    <collision>
      <origin
        xyz="0 0 0"
        rpy="0 0 0" />
      <geometry>
        <mesh
          filename="package://9.SLDASM/meshes/RArm.STL" />
      </geometry>
    </collision>
  </link>
  <joint
    name="RArmPitch"
    type="revolute">
    <origin
      xyz="-0.01 -0.083 -0.0305"
      rpy="0 0 0" />
    <parent
      link="RElbow" />
    <child
      link="RArm" />
    <axis
      xyz="0 1 0" />
    <limit
      lower="-1"
      upper="1"
      effort="1000"
      velocity="10" />
    <dynamics
      damping="1"
      friction="1" />
  </joint>
  <link
    name="RWrist1">
    <inertial>
      <origin
        xyz="-8.69257804625434E-09 -1.11022302462516E-16 -8.69257799074319E-09"
        rpy="0 0 0" />
      <mass
        value="0.00354841244692995" />
      <inertia
        ixx="2.55224026399827E-07"
        ixy="-2.77348371382193E-13"
        ixz="-2.68188677386964E-19"
        iyy="4.81502399048945E-07"
        iyz="2.77348371673297E-13"
        izz="2.55224026399827E-07" />
    </inertial>
    <visual>
      <origin
        xyz="0 0 0"
        rpy="0 0 0" />
      <geometry>
        <mesh
          filename="package://9.SLDASM/meshes/RWrist1.STL" />
      </geometry>
      <material
        name="temp">
        <color
          rgba="1 1 1 1" />
      </material>
    </visual>
    <collision>
      <origin
        xyz="0 0 0"
        rpy="0 0 0" />
      <geometry>
        <mesh
          filename="package://9.SLDASM/meshes/RWrist1.STL" />
      </geometry>
    </collision>
  </link>
  <joint
    name="RWristRoll"
    type="revolute">
    <origin
      xyz="0 -0.124 0"
      rpy="0 0 0" />
    <parent
      link="RArm" />
    <child
      link="RWrist1" />
    <axis
      xyz="1 0 0" />
    <limit
      lower="-1"
      upper="1"
      effort="1000"
      velocity="10" />
    <dynamics
      damping="1"
      friction="1" />
  </joint>
  <link
    name="RWrist2">
    <inertial>
      <origin
        xyz="-0.0032015407111433 -0.0680002451287101 -0.00139605167258255"
        rpy="0 0 0" />
      <mass
        value="0.106500992906003" />
      <inertia
        ixx="0.000160137434624347"
        ixy="1.50250606985986E-05"
        ixz="8.08883042716908E-06"
        iyy="7.18756092477474E-05"
        iyz="5.84436693809921E-06"
        izz="0.000161241258582528" />
    </inertial>
    <visual>
      <origin
        xyz="0 0 0"
        rpy="0 0 0" />
      <geometry>
        <mesh
          filename="package://9.SLDASM/meshes/RWrist2.STL" />
      </geometry>
      <material
        name="temp">
        <color
          rgba="1 1 1 1" />
      </material>
    </visual>
    <collision>
      <origin
        xyz="0 0 0"
        rpy="0 0 0" />
      <geometry>
        <mesh
          filename="package://9.SLDASM/meshes/RWrist2.STL" />
      </geometry>
    </collision>
  </link>
  <joint
    name="RWristYaw"
    type="revolute">
    <origin
      xyz="0 0 0"
      rpy="0 0 0" />
    <parent
      link="RWrist1" />
    <child
      link="RWrist2" />
    <axis
      xyz="0 0 1" />
    <limit
      lower="-1"
      upper="1"
      effort="1000"
      velocity="10" />
    <dynamics
      damping="1"
      friction="1" />
  </joint>
  <link
    name="LShoulder1">
    <inertial>
      <origin
        xyz="0.0119102663222135 0.044680169164134 0.0125101838399666"
        rpy="0 0 0" />
      <mass
        value="0.703972240590069" />
      <inertia
        ixx="0.00106958029541502"
        ixy="4.31046051165897E-05"
        ixz="-1.25610545954009E-05"
        iyy="0.00208834082537485"
        iyz="1.35987436285722E-05"
        izz="0.00181405089345679" />
    </inertial>
    <visual>
      <origin
        xyz="0 0 0"
        rpy="0 0 0" />
      <geometry>
        <mesh
          filename="package://9.SLDASM/meshes/LShoulder1.STL" />
      </geometry>
      <material
        name="temp">
        <color
          rgba="1 1 1 1" />
      </material>
    </visual>
    <collision>
      <origin
        xyz="0 0 0"
        rpy="0 0 0" />
      <geometry>
        <mesh
          filename="package://9.SLDASM/meshes/LShoulder1.STL" />
      </geometry>
    </collision>
  </link>
  <joint
    name="LShoulder1Pitch"
    type="revolute">
    <origin
      xyz="0.0081623 0.12308 0.255"
      rpy="0 0 -0.18497" />
    <parent
      link="Torso" />
    <child
      link="LShoulder1" />
    <axis
      xyz="0 1 0" />
    <limit
      lower="-1"
      upper="1"
      effort="1000"
      velocity="10" />
    <dynamics
      damping="1"
      friction="1" />
  </joint>
  <link
    name="LShoulder2">
    <inertial>
      <origin
        xyz="0.0512392400737466 0.0264143370365393 0.0012076909283113"
        rpy="0 0 0" />
      <mass
        value="0.710520459771819" />
      <inertia
        ixx="0.00114546112171041"
        ixy="-1.88293434343879E-05"
        ixz="-1.50917387927519E-06"
        iyy="0.000678754020646653"
        iyz="1.74648361634084E-05"
        izz="0.0011825421207912" />
    </inertial>
    <visual>
      <origin
        xyz="0 0 0"
        rpy="0 0 0" />
      <geometry>
        <mesh
          filename="package://9.SLDASM/meshes/LShoulder2.STL" />
      </geometry>
      <material
        name="temp">
        <color
          rgba="1 1 1 1" />
      </material>
    </visual>
    <collision>
      <origin
        xyz="0 0 0"
        rpy="0 0 0" />
      <geometry>
        <mesh
          filename="package://9.SLDASM/meshes/LShoulder2.STL" />
      </geometry>
    </collision>
  </link>
  <joint
    name="LShoulder2Roll"
    type="revolute">
    <origin
      xyz="-0.05 0.0709 0"
      rpy="0 0 0" />
    <parent
      link="LShoulder1" />
    <child
      link="LShoulder2" />
    <axis
      xyz="1 0 0" />
    <limit
      lower="-1"
      upper="1"
      effort="1000"
      velocity="10" />
    <dynamics
      damping="1"
      friction="1" />
  </joint>
  <link
    name="LShoulder3">
    <inertial>
      <origin
        xyz="-0.000285011372341666 0.0754226804882471 0.000610240061953593"
        rpy="0 0 0" />
      <mass
        value="0.924000387078446" />
      <inertia
        ixx="0.00281486815062724"
        ixy="2.01811427412035E-05"
        ixz="1.60698461086991E-06"
        iyy="0.001117411560517"
        iyz="2.74171545891918E-05"
        izz="0.00248622929669194" />
    </inertial>
    <visual>
      <origin
        xyz="0 0 0"
        rpy="0 0 0" />
      <geometry>
        <mesh
          filename="package://9.SLDASM/meshes/LShoulder3.STL" />
      </geometry>
      <material
        name="temp">
        <color
          rgba="1 1 1 1" />
      </material>
    </visual>
    <collision>
      <origin
        xyz="0 0 0"
        rpy="0 0 0" />
      <geometry>
        <mesh
          filename="package://9.SLDASM/meshes/LShoulder3.STL" />
      </geometry>
    </collision>
  </link>
  <joint
    name="LShoulder3Pitch"
    type="revolute">
    <origin
      xyz="0.04975 0.0847 0"
      rpy="0 0 0" />
    <parent
      link="LShoulder2" />
    <child
      link="LShoulder3" />
    <axis
      xyz="0 1 0" />
    <limit
      lower="-1"
      upper="1"
      effort="1000"
      velocity="10" />
    <dynamics
      damping="1"
      friction="1" />
  </joint>
  <link
    name="LElbow">
    <inertial>
      <origin
        xyz="-0.00649287860201503 0.0268919766798237 -0.0306567508285921"
        rpy="0 0 0" />
      <mass
        value="0.0670906547261469" />
      <inertia
        ixx="0.0001090358344894"
        ixy="-6.74241047758024E-06"
        ixz="-1.64115699849976E-07"
        iyy="8.7461529022883E-05"
        iyz="6.51839288561937E-07"
        izz="0.000124731354151367" />
    </inertial>
    <visual>
      <origin
        xyz="0 0 0"
        rpy="0 0 0" />
      <geometry>
        <mesh
          filename="package://9.SLDASM/meshes/LElbow.STL" />
      </geometry>
      <material
        name="temp">
        <color
          rgba="1 1 1 1" />
      </material>
    </visual>
    <collision>
      <origin
        xyz="0 0 0"
        rpy="0 0 0" />
      <geometry>
        <mesh
          filename="package://9.SLDASM/meshes/LElbow.STL" />
      </geometry>
    </collision>
  </link>
  <joint
    name="LElbowYaw"
    type="revolute">
    <origin
      xyz="0.01 0.1485 0.0305"
      rpy="0 0 0" />
    <parent
      link="LShoulder3" />
    <child
      link="LElbow" />
    <axis
      xyz="0 0 1" />
    <limit
      lower="-1"
      upper="1"
      effort="1000"
      velocity="10" />
    <dynamics
      damping="1"
      friction="1" />
  </joint>
  <link
    name="LArm">
    <inertial>
      <origin
        xyz="4.78492893404847E-07 0.0546540523030666 0.000345579805242358"
        rpy="0 0 0" />
      <mass
        value="0.698818860634211" />
      <inertia
        ixx="0.00106001756026175"
        ixy="1.21255797364553E-08"
        ixz="9.70520459720007E-10"
        iyy="0.000705558851650975"
        iyz="-3.04830728342831E-06"
        izz="0.00107111332490694" />
    </inertial>
    <visual>
      <origin
        xyz="0 0 0"
        rpy="0 0 0" />
      <geometry>
        <mesh
          filename="package://9.SLDASM/meshes/LArm.STL" />
      </geometry>
      <material
        name="temp">
        <color
          rgba="1 1 1 1" />
      </material>
    </visual>
    <collision>
      <origin
        xyz="0 0 0"
        rpy="0 0 0" />
      <geometry>
        <mesh
          filename="package://9.SLDASM/meshes/LArm.STL" />
      </geometry>
    </collision>
  </link>
  <joint
    name="LArmPitch"
    type="revolute">
    <origin
      xyz="-0.01 0.083 -0.0305"
      rpy="0 0 0" />
    <parent
      link="LElbow" />
    <child
      link="LArm" />
    <axis
      xyz="0 1 0" />
    <limit
      lower="-1"
      upper="1"
      effort="1000"
      velocity="10" />
    <dynamics
      damping="1"
      friction="1" />
  </joint>
  <link
    name="LWrist1">
    <inertial>
      <origin
        xyz="8.69257801849876E-09 0 -8.69257799074319E-09"
        rpy="0 0 0" />
      <mass
        value="0.00354841244692992" />
      <inertia
        ixx="2.55224026399827E-07"
        ixy="-2.77348371541011E-13"
        ixz="2.68656438001341E-19"
        iyy="4.81502399048942E-07"
        iyz="-2.77348371751792E-13"
        izz="2.55224026399825E-07" />
    </inertial>
    <visual>
      <origin
        xyz="0 0 0"
        rpy="0 0 0" />
      <geometry>
        <mesh
          filename="package://9.SLDASM/meshes/LWrist1.STL" />
      </geometry>
      <material
        name="temp">
        <color
          rgba="1 1 1 1" />
      </material>
    </visual>
    <collision>
      <origin
        xyz="0 0 0"
        rpy="0 0 0" />
      <geometry>
        <mesh
          filename="package://9.SLDASM/meshes/LWrist1.STL" />
      </geometry>
    </collision>
  </link>
  <joint
    name="LWristRoll"
    type="revolute">
    <origin
      xyz="0 0.124 0"
      rpy="0 0 0" />
    <parent
      link="LArm" />
    <child
      link="LWrist1" />
    <axis
      xyz="1 0 0" />
    <limit
      lower="-1"
      upper="1"
      effort="1000"
      velocity="10" />
    <dynamics
      damping="1"
      friction="1" />
  </joint>
  <link
    name="LWrist2">
    <inertial>
      <origin
        xyz="-0.00320146376134629 0.0679998358897447 -0.00139578498789278"
        rpy="0 0 0" />
      <mass
        value="0.106503207491186" />
      <inertia
        ixx="0.000160140258431206"
        ixy="-1.50255959162748E-05"
        ixz="8.08904875658516E-06"
        iyy="7.18787865803972E-05"
        iyz="-5.84466814549343E-06"
        izz="0.000161242457643774" />
    </inertial>
    <visual>
      <origin
        xyz="0 0 0"
        rpy="0 0 0" />
      <geometry>
        <mesh
          filename="package://9.SLDASM/meshes/LWrist2.STL" />
      </geometry>
      <material
        name="temp">
        <color
          rgba="1 1 1 1" />
      </material>
    </visual>
    <collision>
      <origin
        xyz="0 0 0"
        rpy="0 0 0" />
      <geometry>
        <mesh
          filename="package://9.SLDASM/meshes/LWrist2.STL" />
      </geometry>
    </collision>
  </link>
  <joint
    name="LWristYaw"
    type="revolute">
    <origin
      xyz="0 0 0"
      rpy="0 0 0" />
    <parent
      link="LWrist1" />
    <child
      link="LWrist2" />
    <axis
      xyz="0 0 1" />
    <limit
      lower="-1"
      upper="1"
      effort="1000"
      velocity="10" />
    <dynamics
      damping="1"
      friction="1" />
  </joint>
</robot>